<?xml version="1.0" encoding="utf-8"?>
<!-- This URDF was automatically created by SolidWorks to URDF Exporter! Originally created by Stephen Brawner (brawner@gmail.com) 
     Commit Version: 1.5.1-0-g916b5db  Build Version: 1.5.7152.31018
     For more information, please see http://wiki.ros.org/sw_urdf_exporter -->
<robot
  name="adept_robot_2">
  <link
    name="base_link">
    <inertial>
      <origin
        xyz="0.0245 -0.0001542 0.21373"
        rpy="0 0 0" />
      <mass
        value="2.5675" />
      <inertia
        ixx="0.0068861"
        ixy="5.4055E-11"
        ixz="5.5326E-05"
        iyy="0.0063943"
        iyz="-3.5928E-12"
        izz="0.0057933" />
    </inertial>
    <visual>
      <origin
        xyz="0 0 0"
        rpy="0 0 0" />
      <geometry>
        <mesh
          filename="package://adept_robot_2/meshes/base_link.STL" />
      </geometry>
      <material
        name="">
        <color
          rgba="1 1 1 0.32" />
      </material>
    </visual>
    <collision>
      <origin
        xyz="0 0 0"
        rpy="0 0 0" />
      <geometry>
        <mesh
          filename="package://adept_robot_2/meshes/base_link.STL" />
      </geometry>
    </collision>
  </link>
  <link
    name="Link1">
    <inertial>
      <origin
        xyz="0.117407025872708 -1.25359334024466E-10 -0.0275548145030767"
        rpy="0 0 0" />
      <mass
        value="0.569125964077184" />
      <inertia
        ixx="0.000395436813571713"
        ixy="5.37455807300204E-13"
        ixz="0.000124545644672777"
        iyy="0.00223952834304756"
        iyz="3.5503068082669E-13"
        izz="0.00211092523046064" />
    </inertial>
    <visual>
      <origin
        xyz="0 0 0"
        rpy="0 0 0" />
      <geometry>
        <mesh
          filename="package://adept_robot_2/meshes/Link1.STL" />
      </geometry>
      <material
        name="">
        <color
          rgba="1 1 1 1" />
      </material>
    </visual>
    <collision>
      <origin
        xyz="0 0 0"
        rpy="0 0 0" />
      <geometry>
        <mesh
          filename="package://adept_robot_2/meshes/Link1.STL" />
      </geometry>
    </collision>
  </link>
  <joint
    name="Joint1"
    type="revolute">
    <origin
      xyz="0.10571 -0.0001601 0.42988"
      rpy="0 0 0" />
    <parent
      link="base_link" />
    <child
      link="Link1" />
    <axis
      xyz="0 0 1" />
    <limit
      lower="-2"
      upper="2"
      effort="0"
      velocity="1" />
  </joint>
  <link
    name="Link2">
    <inertial>
      <origin
        xyz="0.0829498912742016 0.00283016633079733 0.00977088530359421"
        rpy="0 0 0" />
      <mass
        value="0.212874058038776" />
      <inertia
        ixx="6.57074308602495E-05"
        ixy="-1.74128836487361E-05"
        ixz="8.4823788307751E-06"
        iyy="0.000390393473487716"
        iyz="7.84228298422962E-07"
        izz="0.000425987376929657" />
    </inertial>
    <visual>
      <origin
        xyz="0 0 0"
        rpy="0 0 0" />
      <geometry>
        <mesh
          filename="package://adept_robot_2/meshes/Link2.STL" />
      </geometry>
      <material
        name="">
        <color
          rgba="1 1 1 1" />
      </material>
    </visual>
    <collision>
      <origin
        xyz="0 0 0"
        rpy="0 0 0" />
      <geometry>
        <mesh
          filename="package://adept_robot_2/meshes/Link2.STL" />
      </geometry>
    </collision>
  </link>
  <joint
    name="Joint2"
    type="revolute">
    <origin
      xyz="0.19 0 -0.035"
      rpy="0 0 0" />
    <parent
      link="Link1" />
    <child
      link="Link2" />
    <axis
      xyz="0 0 1" />
    <limit
      lower="-2"
      upper="2"
      effort="0"
      velocity="1" />
  </joint>
  <link
    name="Tool">
    <inertial>
      <origin
        xyz="-4.27651823747821E-06 -0.00299987625965217 0.0348778462843223"
        rpy="0 0 0" />
      <mass
        value="0.023545411123381" />
      <inertia
        ixx="4.56549098366953E-05"
        ixy="-7.94158153472426E-09"
        ixz="-4.55664961256907E-09"
        iyy="4.00718283641911E-05"
        iyz="-3.17465425925388E-06"
        izz="6.99639144528093E-06" />
    </inertial>
    <visual>
      <origin
        xyz="0 0 0"
        rpy="0 0 0" />
      <geometry>
        <mesh
          filename="package://adept_robot_2/meshes/Tool.STL" />
      </geometry>
      <material
        name="">
        <color
          rgba="1 1 1 1" />
      </material>
    </visual>
    <collision>
      <origin
        xyz="0 0 0"
        rpy="0 0 0" />
      <geometry>
        <mesh
          filename="package://adept_robot_2/meshes/Tool.STL" />
      </geometry>
    </collision>
  </link>
  <joint
    name="Tool1"
    type="prismatic">
    <origin
      xyz="0.12 0 -0.14263"
      rpy="-3.1416 0 0" />
    <parent
      link="Link2" />
    <child
      link="Tool" />
    <axis
      xyz="0 0 1" />
    <limit
      lower="0"
      upper="0.06"
      effort="0"
      velocity="0.075" />
  </joint>
  <link
    name="Link_4">
    <inertial>
      <origin
        xyz="-0.000623533590957182 0.00434070055352537 0.0430465440289566"
        rpy="0 0 0" />
      <mass
        value="0.0317141760755607" />
      <inertia
        ixx="7.93928844844214E-06"
        ixy="-2.50593233840946E-12"
        ixz="-1.72426138157143E-07"
        iyy="1.11018333375248E-05"
        iyz="-4.41698963488257E-08"
        izz="4.27099015161773E-06" />
    </inertial>
    <visual>
      <origin
        xyz="0 0 0"
        rpy="0 0 0" />
      <geometry>
        <mesh
          filename="package://adept_robot_2/meshes/Link_4.STL" />
      </geometry>
      <material
        name="">
        <color
          rgba="1 1 1 0.32" />
      </material>
    </visual>
    <collision>
      <origin
        xyz="0 0 0"
        rpy="0 0 0" />
      <geometry>
        <mesh
          filename="package://adept_robot_2/meshes/Link_4.STL" />
      </geometry>
    </collision>
  </link>
  <joint
    name="Revolute4"
    type="revolute">
    <origin
      xyz="0.00013701 0 0.125"
      rpy="0 0 0" />
    <parent
      link="Tool" />
    <child
      link="Link_4" />
    <axis
      xyz="0 0 1" />
    <limit
      lower="-1.57"
      upper="1.57"
      effort="0"
      velocity="0.5" />
  </joint>
  <link
    name="RigidBody">
    <inertial>
      <origin
        xyz="-1.5837449969025E-05 -0.0109655938473857 -0.0707365158487714"
        rpy="0 0 0" />
      <mass
        value="0.0516096083407531" />
      <inertia
        ixx="9.35418438432533E-05"
        ixy="4.09021495360865E-12"
        ixz="1.90900339264504E-10"
        iyy="9.35989189378686E-05"
        iyz="3.12076345540328E-10"
        izz="5.9086012596584E-07" />
    </inertial>
    <visual>
      <origin
        xyz="0 0 0"
        rpy="0 0 0" />
      <geometry>
        <mesh
          filename="package://adept_robot_2/meshes/RigidBody.STL" />
      </geometry>
      <material
        name="">
        <color
          rgba="1 1 1 1" />
      </material>
    </visual>
    <collision>
      <origin
        xyz="0 0 0"
        rpy="0 0 0" />
      <geometry>
        <mesh
          filename="package://adept_robot_2/meshes/RigidBody.STL" />
      </geometry>
    </collision>
  </link>
  <joint
    name="Fixed_Body"
    type="fixed">
    <origin
      xyz="0.12 0 -0.14263"
      rpy="-3.1416 0 0" />
    <parent
      link="Link2" />
    <child
      link="RigidBody" />
    <axis
      xyz="0 0 0" />
    <limit
      lower="0"
      upper="0"
      effort="0"
      velocity="0" />
    <safety_controller
      soft_upper="0"
      soft_lower="0"
      k_position="0"
      k_velocity="0" />
  </joint>
</robot>