<?xml version="1.0" encoding="utf-8"?>
<!-- This URDF was automatically created by SolidWorks to URDF Exporter! Originally created by Stephen Brawner (brawner@gmail.com) 
     Commit Version: 1.5.1-0-g916b5db  Build Version: 1.5.7152.31018
     For more information, please see http://wiki.ros.org/sw_urdf_exporter -->
<robot
  name="SCARA_robot_2">
  <link
    name="base_link">
    <inertial>
      <origin
        xyz="0.0245 -0.0001542 0.21373"
        rpy="0 0 0" />
      <mass
        value="2.5675" />
      <inertia
        ixx="0.0068861"
        ixy="5.4055E-11"
        ixz="5.5326E-05"
        iyy="0.0063943"
        iyz="-3.5928E-12"
        izz="0.0057933" />
    </inertial>
    <visual>
      <origin
        xyz="0 0 0"
        rpy="0 0 0" />
      <geometry>
        <mesh
          filename="package://SCARA_robot_2/meshes/base_link.STL" />
      </geometry>
      <material
        name="">
        <color
          rgba="1 1 1 0.32" />
      </material>
    </visual>
    <collision>
      <origin
        xyz="0 0 0"
        rpy="0 0 0" />
      <geometry>
        <mesh
          filename="package://SCARA_robot_2/meshes/base_link.STL" />
      </geometry>
    </collision>
  </link>
  <link
    name="Link1">
    <inertial>
      <origin
        xyz="0.11741 -1.2536E-10 0.17845"
        rpy="0 0 0" />
      <mass
        value="0.56913" />
      <inertia
        ixx="0.00039544"
        ixy="5.3746E-13"
        ixz="0.00012455"
        iyy="0.0022395"
        iyz="3.5503E-13"
        izz="0.0021109" />
    </inertial>
    <visual>
      <origin
        xyz="0 0 0"
        rpy="0 0 0" />
      <geometry>
        <mesh
          filename="package://SCARA_robot_2/meshes/Link1.STL" />
      </geometry>
      <material
        name="">
        <color
          rgba="1 1 1 1" />
      </material>
    </visual>
    <collision>
      <origin
        xyz="0 0 0"
        rpy="0 0 0" />
      <geometry>
        <mesh
          filename="package://SCARA_robot_2/meshes/Link1.STL" />
      </geometry>
    </collision>
  </link>
  <joint
    name="Joint1"
    type="revolute">
    <origin
      xyz="0.10571 -0.0001601 0.22388"
      rpy="0 0 0" />
    <parent
      link="base_link" />
    <child
      link="Link1" />
    <axis
      xyz="0 0 1" />
    <limit
      lower="-2"
      upper="2"
      effort="0"
      velocity="1" />
  </joint>
  <link
    name="Link2">
    <inertial>
      <origin
        xyz="0.08295 0.0028302 0.0097709"
        rpy="0 0 0" />
      <mass
        value="0.21287" />
      <inertia
        ixx="6.5707E-05"
        ixy="-1.7413E-05"
        ixz="8.4824E-06"
        iyy="0.00039039"
        iyz="7.8423E-07"
        izz="0.00042599" />
    </inertial>
    <visual>
      <origin
        xyz="0 0 0"
        rpy="0 0 0" />
      <geometry>
        <mesh
          filename="package://SCARA_robot_2/meshes/Link2.STL" />
      </geometry>
      <material
        name="">
        <color
          rgba="1 1 1 1" />
      </material>
    </visual>
    <collision>
      <origin
        xyz="0 0 0"
        rpy="0 0 0" />
      <geometry>
        <mesh
          filename="package://SCARA_robot_2/meshes/Link2.STL" />
      </geometry>
    </collision>
  </link>
  <joint
    name="Joint2"
    type="revolute">
    <origin
      xyz="0.19 0 0.171"
      rpy="0 0 0" />
    <parent
      link="Link1" />
    <child
      link="Link2" />
    <axis
      xyz="0 0 1" />
    <limit
      lower="-2"
      upper="2"
      effort="0"
      velocity="1" />
  </joint>
  <link
    name="Tool">
    <inertial>
      <origin
        xyz="-4.2765E-06 -0.0029999 0.034878"
        rpy="0 0 0" />
      <mass
        value="0.023545" />
      <inertia
        ixx="4.5655E-05"
        ixy="-7.9416E-09"
        ixz="-4.5566E-09"
        iyy="4.0072E-05"
        iyz="-3.1747E-06"
        izz="6.9964E-06" />
    </inertial>
    <visual>
      <origin
        xyz="0 0 0"
        rpy="0 0 0" />
      <geometry>
        <mesh
          filename="package://SCARA_robot_2/meshes/Tool.STL" />
      </geometry>
      <material
        name="">
        <color
          rgba="1 1 1 1" />
      </material>
    </visual>
    <collision>
      <origin
        xyz="0 0 0"
        rpy="0 0 0" />
      <geometry>
        <mesh
          filename="package://SCARA_robot_2/meshes/Tool.STL" />
      </geometry>
    </collision>
  </link>
  <joint
    name="Tool1"
    type="prismatic">
    <origin
      xyz="0.12 0 -0.14263"
      rpy="-3.1416 0 0" />
    <parent
      link="Link2" />
    <child
      link="Tool" />
    <axis
      xyz="0 0 1" />
    <limit
      lower="0"
      upper="0.06"
      effort="0"
      velocity="0.075" />
  </joint>
  <link
    name="Link_4">
    <inertial>
      <origin
        xyz="-0.00062353 0.0043407 0.043047"
        rpy="0 0 0" />
      <mass
        value="0.031714" />
      <inertia
        ixx="7.9393E-06"
        ixy="-2.5059E-12"
        ixz="-1.7243E-07"
        iyy="1.1102E-05"
        iyz="-4.417E-08"
        izz="4.271E-06" />
    </inertial>
    <visual>
      <origin
        xyz="0 0 0"
        rpy="0 0 0" />
      <geometry>
        <mesh
          filename="package://SCARA_robot_2/meshes/Link_4.STL" />
      </geometry>
      <material
        name="">
        <color
          rgba="1 1 1 0.32" />
      </material>
    </visual>
    <collision>
      <origin
        xyz="0 0 0"
        rpy="0 0 0" />
      <geometry>
        <mesh
          filename="package://SCARA_robot_2/meshes/Link_4.STL" />
      </geometry>
    </collision>
  </link>
  <joint
    name="Revolute4"
    type="revolute">
    <origin
      xyz="0.00013701 0 0.125"
      rpy="0 0 0" />
    <parent
      link="Tool" />
    <child
      link="Link_4" />
    <axis
      xyz="0 0 1" />
    <limit
      lower="-1.57"
      upper="1.57"
      effort="0"
      velocity="0.5" />
  </joint>
  <link
    name="RigidBody">
    <inertial>
      <origin
        xyz="-1.5837E-05 -0.010966 -0.070737"
        rpy="0 0 0" />
      <mass
        value="0.05161" />
      <inertia
        ixx="9.3542E-05"
        ixy="4.0902E-12"
        ixz="1.909E-10"
        iyy="9.3599E-05"
        iyz="3.1208E-10"
        izz="5.9086E-07" />
    </inertial>
    <visual>
      <origin
        xyz="0 0 0"
        rpy="0 0 0" />
      <geometry>
        <mesh
          filename="package://SCARA_robot_2/meshes/RigidBody.STL" />
      </geometry>
      <material
        name="">
        <color
          rgba="1 1 1 1" />
      </material>
    </visual>
    <collision>
      <origin
        xyz="0 0 0"
        rpy="0 0 0" />
      <geometry>
        <mesh
          filename="package://SCARA_robot_2/meshes/RigidBody.STL" />
      </geometry>
    </collision>
  </link>
  <joint
    name="Fixed_Body"
    type="fixed">
    <origin
      xyz="0.12 0 -0.14263"
      rpy="-3.1416 0 0" />
    <parent
      link="Link2" />
    <child
      link="RigidBody" />
    <axis
      xyz="0 0 0" />
    <limit
      lower="0"
      upper="0"
      effort="0"
      velocity="0" />
    <safety_controller
      soft_upper="0"
      soft_lower="0"
      k_position="0"
      k_velocity="0" />
  </joint>
</robot>